Workbook
Name CleanedNikeSales: Cleaned_Nike_Sales!$B$1
Name CleanedSales: Cleaned_Nike_Sales!$B$1:$AA$42
Name Discount_Analysis: Nike_Sales_PreCleaned!$N$2:$N$2501
Name Discount_Applied: Nike_Sales_PreCleaned!$L$2:$L$2501
Name Discount_Verification: Nike_Sales_PreCleaned!$M$2:$M$2501
Name Gender_Category: Nike_Sales_PreCleaned!$B$2:$B$2501
Name MRP: Nike_Sales_PreCleaned!$K$2:$K$2501
Name NikeCleaned: Cleaned_Nike_Sales!#REF!
Name OD_Status: Nike_Sales_PreCleaned!$T$2:$T$2501
Name Order_Date: Nike_Sales_PreCleaned!$S$2:$S$2501
Name Order_ID: Nike_Sales_PreCleaned!$A$2:$A$2501
Name Product_Line: Nike_Sales_PreCleaned!$C$2:$C$2501
Name Product_Name: Nike_Sales_PreCleaned!$D$2:$D$2501
Name Product_Status: Nike_Sales_PreCleaned!$J$2:$J$2501
Name Profit: Nike_Sales_PreCleaned!$Y$2:$Y$2501
Name Profit_Analysis: Nike_Sales_PreCleaned!$AA$2:$AA$2501
Name Profit_Status: Nike_Sales_PreCleaned!$Z$2:$Z$2501
Name Region: Nike_Sales_PreCleaned!$W$2:$W$2501
Name Region_Formatted: Nike_Sales_PreCleaned!$X$2:$X$2501
Name Rev_Recalc: Nike_Sales_PreCleaned!$P$2:$P$2501
Name Rev_Verify: Nike_Sales_PreCleaned!$Q$2:$Q$2501
Name Revenue: Nike_Sales_PreCleaned!$O$2:$O$2501
Name Revenue_Analysis: Nike_Sales_PreCleaned!$R$2:$R$2501
Name Sales_Channel: Nike_Sales_PreCleaned!$V$2:$V$2501
Name Size: Nike_Sales_PreCleaned!$E$2:$E$2501
Name Size_Type: Nike_Sales_PreCleaned!$F$2:$F$2501
Name Size_Verification: Nike_Sales_PreCleaned!$G$2:$G$2501
Name Units_Sold: Nike_Sales_PreCleaned!$I$2:$I$2501
Name Valid_OD_Analysis: Nike_Sales_PreCleaned!$U$2:$U$2501
Name Valid_Size_Analysis: Nike_Sales_PreCleaned!$H$2:$H$2501

Sheet Nike_Sales_RawData
A1: Order_ID | B1: Gender_Category | C1: Product_Line | D1: Product_Name | E1: Size | F1: Units_Sold | G1: MRP | H1: Discount_Applied | I1: Revenue | J1: Order_Date | K1: Sales_Channel | L1: Region | M1: Profit
A2: 2053 | B2: Men | C2: Lifestyle | D2: Air Force 1 | E2: XL | F2: 3 | G2: 6009.58 | I2: 0 | J2: 45567 | K2: Online | L2: Delhi | M2: 3384.92
A3: 2108 | B3: Kids | C3: Lifestyle | D3: Air Force 1 | E3: XL | H3: 0.27 | I3: 0 | J3: 45611 | K3: Retail | L3: Mumbai | M3: -338.77
A4: 2166 | B4: Women | C4: Lifestyle | D4: Air Force 1 | E4: M | G4: 7312.38 | I4: 0 | J4: 45689 | K4: Online | L4: Mumbai | M4: 3364.05
A5: 2170 | B5: Kids | C5: Lifestyle | D5: Air Force 1 | E5: M | F5: 0 | I5: 0 | J5: 45836 | K5: Online | L5: Kolkata | M5: 3218.82
A6: 2022 | B6: Women | C6: Lifestyle | D6: Air Force 1 | E6: L | G6: 9378.52 | H6: 1.06 | I6: 0 | J6: 45228 | K6: Retail | L6: Mumbai | M6: 128.92
A7: 2181 | B7: Women | C7: Lifestyle | D7: Air Force 1 | E7: XL | F7: 2 | I7: 0 | J7: 45663 | K7: Retail | L7: Delhi | M7: 419.58
A8: 2191 | B8: Men | C8: Lifestyle | D8: Air Force 1 | E8: 8 | F8: 3 | I8: 0 | J8: 45563 | K8: Retail | L8: Pune | M8: -1032.88
A9: 2203 | B9: Men | C9: Lifestyle | D9: Air Force 1 | E9: M | F9: 0 | G9: 6903.22 | I9: 0 | K9: Online | L9: Pune | M9: 1556.95
A10: 2216 | B10: Women | C10: Lifestyle | D10: Air Force 1 | E10: M | F10: 1 | G10: 3111.62 | I10: 0 | K10: Online | L10: Hyd | M10: 2617.56
A11: 2233 | B11: Men | C11: Lifestyle | D11: Air Force 1 | E11: XL | F11: 0 | I11: 0 | K11: Online | L11: Kolkata | M11: 2398.07
A12: 2276 | B12: Kids | C12: Lifestyle | D12: Air Force 1 | E12: L | F12: -1 | G12: 6066.5 | I12: 0 | J12: 45167 | K12: Retail | L12: Kolkata | M12: 1181.87
A13: 2357 | B13: Women | C13: Lifestyle | D13: Air Force 1 | E13: M | H13: 1.23 | I13: 0 | J13: 45775 | K13: Retail | L13: Bangalore | M13: -1199.32
A14: 2373 | B14: Women | C14: Lifestyle | D14: Air Force 1 | E14: XL | G14: 8637.25 | H14: 0.35 | I14: 0 | J14: 45557 | K14: Retail | L14: Kolkata | M14: 2738.82
A15: 2379 | B15: Men | C15: Lifestyle | D15: Air Force 1 | E15: L | F15: 4 | I15: 0 | J15: 45391 | K15: Online | L15: Mumbai | M15: 3289.77
A16: 2394 | B16: Kids | C16: Lifestyle | D16: Air Force 1 | E16: XL | H16: 0.2 | I16: 0 | J16: 45156 | K16: Online | L16: Delhi | M16: -133.03
A17: 2482 | B17: Men | C17: Lifestyle | D17: Air Force 1 | E17: XL | I17: 0 | J17: 45549 | K17: Online | L17: Mumbai | M17: 2642.8
A18: 2489 | B18: Men | C18: Lifestyle | D18: Air Force 1 | F18: 4 | H18: 0.18 | I18: 0 | J18: 45567 | K18: Retail | L18: hyderbad | M18: 1415.34
A19: 2501 | B19: Women | C19: Lifestyle | D19: Air Force 1 | E19: L | G19: 6453.36 | I19: 0 | J19: 45812 | K19: Retail | L19: Kolkata | M19: 2321.06
A20: 2517 | B20: Men | C20: Lifestyle | D20: Air Force 1 | E20: 7 | F20: 1 | G20: 3059.89 | I20: 0 | K20: Online | L20: hyderbad | M20: 1968.82
A21: 2524 | B21: Women | C21: Lifestyle | D21: Air Force 1 | E21: XL | I21: 0 | J21: 45617 | K21: Online | L21: Kolkata | M21: 997.53
A22: 2527 | B22: Men | C22: Lifestyle | D22: Air Force 1 | E22: XL | G22: 7408.91 | I22: 0 | J22: 45369 | K22: Online | L22: Delhi | M22: -138.78
A23: 2540 | B23: Women | C23: Lifestyle | D23: Air Force 1 | E23: L | G23: 8794.64 | I23: 0 | J23: 45666 | K23: Online | L23: Mumbai | M23: -938.07
A24: 2556 | B24: Kids | C24: Lifestyle | D24: Air Force 1 | E24: 10 | F24: 1 | I24: 0 | K24: Retail | L24: Kolkata | M24: 1327.26
A25: 2559 | B25: Men | C25: Lifestyle | D25: Air Force 1 | E25: 7 | F25: 3 | G25: 6011.84 | I25: 0 | J25: 45698 | K25: Online | L25: Kolkata | M25: -99.73
A26: 2600 | B26: Kids | C26: Lifestyle | D26: Air Force 1 | E26: M | F26: 3 | I26: 0 | J26: 45600 | K26: Online | L26: Pune | M26: 803.62
A27: 2606 | B27: Women | C27: Lifestyle | D27: Air Force 1 | E27: L | G27: 4040.65 | I27: 0 | J27: 45812 | K27: Retail | L27: Mumbai | M27: 805.92
A28: 2642 | B28: Women | C28: Lifestyle | D28: Air Force 1 | E28: XL | I28: 0 | J28: 45794 | K28: Retail | L28: Pune | M28: -785.16
A29: 2667 | B29: Women | C29: Lifestyle | D29: Air Force 1 | E29: XL | F29: 3 | G29: 9367.66 | I29: 0 | J29: 45739 | K29: Online | L29: Delhi | M29: -623.95
A30: 2672 | B30: Women | C30: Lifestyle | D30: Air Force 1 | E30: XL | F30: 2 | I30: 0 | J30: 45508 | K30: Online | L30: Mumbai | M30: 67.58
A31: 2677 | B31: Men | C31: Lifestyle | D31: Air Force 1 | E31: M | F31: 2 | G31: 5618.62 | I31: 0 | K31: Retail | L31: bengaluru | M31: 1745.96
A32: 2713 | B32: Men | C32: Lifestyle | D32: Air Force 1 | E32: L | F32: 1 | G32: 7877.36 | H32: 0.55 | I32: 3544.81 | J32: 45787 | K32: Retail | L32: Kolkata | M32: 3663.49
A33: 2740 | B33: Women | C33: Lifestyle | D33: Air Force 1 | E33: XL | F33: 1 | G33: 4922.19 | I33: 0 | K33: Retail | L33: bengaluru | M33: 3820.48
A34: 2775 | B34: Men | C34: Lifestyle | D34: Air Force 1 | H34: 0.73 | I34: 0 | K34: Online | L34: Pune | M34: 2329.33
A35: 2821 | B35: Kids | C35: Lifestyle | D35: Air Force 1 | F35: 0 | G35: 3360.35 | I35: 0 | J35: 45755 | K35: Online | L35: Delhi | M35: 2991.25
A36: 2835 | B36: Women | C36: Lifestyle | D36: Air Force 1 | G36: 9240.64 | H36: 0.63 | I36: 0 | J36: 45572 | K36: Retail | L36: Pune | M36: 1873.76
A37: 2858 | B37: Kids | C37: Lifestyle | D37: Air Force 1 | F37: 0 | H37: 0.6 | I37: 0 | J37: 45591 | K37: Retail | L37: Pune | M37: 2847.01
A38: 2859 | B38: Women | C38: Lifestyle | D38: Air Force 1 | E38: 7 | I38: 0 | K38: Online | L38: Pune | M38: 566.34
A39: 2860 | B39: Kids | C39: Lifestyle | D39: Air Force 1 | E39: XL | F39: -1 | G39: 7568.04 | I39: 0 | J39: 45754 | K39: Retail | L39: hyderbad | M39: 1365.3
A40: 2894 | B40: Women | C40: Lifestyle | D40: Air Force 1 | E40: L | I40: 0 | J40: 45616 | K40: Retail | L40: hyderbad | M40: 1796.17
...

Sheet Pivot Checks
A3: Row Labels | B3: Count of Gender_Category | D3: Row Labels | E3: Count of Size | G3: Count of Order_ID | H3: Column Labels | U3: Count of Size_Type | V3: Column Labels
A4: Kids | B4: 841 | D4: 6 | E4: 59 | G4: Row Labels | H4: 10 | I4: 11 | J4: 12 | K4: 6 | L4: 7 | M4: 8 | N4: 9 | O4: L | P4: M | Q4: Unknown | R4: XL | S4: Grand Total | U4: Row Labels | V4: Alphabet | W4: Missing | X4: Number | Y4: Grand Total
A5: Men | B5: 840 | D5: 7 | E5: 86 | G5: Air Force 1 | H5: 1 | I5: 5 | J5: 1 | K5: 5 | L5: 5 | M5: 2 | N5: 8 | O5: 32 | P5: 18 | Q5: 20 | R5: 24 | S5: 121 | U5: Basketball | V5: 319 | W5: 103 | X5: 85 | Y5: 507
A6: Women | B6: 819 | D6: 8 | E6: 60 | G6: Air Jordan | H6: 7 | I6: 7 | J6: 3 | K6: 3 | L6: 1 | M6: 2 | N6: 5 | O6: 28 | P6: 15 | Q6: 24 | R6: 38 | S6: 133 | U6: Lifestyle | V6: 311 | W6: 93 | X6: 97 | Y6: 501
A7: Grand Total | B7: 2500 | D7: 9 | E7: 68 | G7: Air Zoom | H7: 5 | I7: 2 | J7: 5 | K7: 2 | L7: 6 | M7: 2 | N7: 1 | O7: 23 | P7: 22 | Q7: 18 | R7: 21 | S7: 107 | U7: Running | V7: 282 | W7: 99 | X7: 93 | Y7: 474
D8: 10 | E8: 76 | G8: Blazer Mid | H8: 4 | I8: 1 | J8: 3 | K8: 2 | L8: 4 | M8: 4 | N8: 5 | O8: 30 | P8: 20 | Q8: 22 | R8: 32 | S8: 127 | U8: Soccer | V8: 273 | W8: 100 | X8: 99 | Y8: 472
A9: Row Labels | B9: Count of Product_Line | D9: 11 | E9: 77 | G9: Dunk Low | H9: 4 | I9: 4 | J9: 5 | L9: 5 | M9: 5 | N9: 3 | O9: 22 | P9: 21 | Q9: 25 | R9: 22 | S9: 116 | U9: Training | V9: 318 | W9: 115 | X9: 113 | Y9: 546
A10: Basketball | B10: 507 | D10: 12 | E10: 61 | G10: Flex Trainer | H10: 3 | I10: 8 | J10: 7 | K10: 1 | L10: 2 | M10: 3 | N10: 6 | O10: 27 | P10: 30 | Q10: 23 | R10: 31 | S10: 141 | U10: Grand Total | V10: 1503 | W10: 510 | X10: 487 | Y10: 2500
A11: Lifestyle | B11: 501 | D11: L | E11: 513 | G11: Free RN | H11: 6 | I11: 3 | J11: 4 | K11: 4 | L11: 5 | M11: 3 | N11: 1 | O11: 24 | P11: 21 | Q11: 29 | R11: 24 | S11: 124
A12: Running | B12: 474 | D12: M | E12: 478 | G12: Kyrie Flytrap | H12: 2 | I12: 3 | J12: 4 | K12: 3 | L12: 3 | M12: 2 | N12: 1 | O12: 30 | P12: 17 | Q12: 22 | R12: 29 | S12: 116
A13: Soccer | B13: 472 | D13: XL | E13: 512 | G13: LeBron 20 | H13: 2 | I13: 3 | J13: 2 | K13: 6 | L13: 5 | M13: 1 | N13: 1 | O13: 30 | P13: 30 | Q13: 29 | R13: 35 | S13: 144
A14: Training | B14: 546 | D14: (blank) | G14: Mercurial Superfly | H14: 5 | I14: 1 | J14: 2 | K14: 1 | L14: 3 | M14: 2 | N14: 5 | O14: 17 | P14: 32 | Q14: 28 | R14: 13 | S14: 109
A15: Grand Total | B15: 2500 | D15: Grand Total | E15: 1990 | G15: Metcon 7 | H15: 1 | I15: 1 | J15: 3 | K15: 6 | L15: 4 | M15: 5 | N15: 2 | O15: 18 | P15: 29 | Q15: 20 | R15: 28 | S15: 117
G16: Pegasus Turbo | H16: 3 | I16: 4 | K16: 2 | L16: 5 | M16: 4 | N16: 5 | O16: 27 | P16: 15 | Q16: 26 | R16: 18 | S16: 109
A17: Row Labels | B17: Count of Product_Name | D17: Row Labels | E17: Count of Region_Formatted | G17: Phantom GT | H17: 2 | I17: 3 | J17: 3 | K17: 5 | L17: 9 | M17: 5 | N17: 3 | O17: 20 | P17: 22 | Q17: 32 | R17: 26 | S17: 130
A18: Air Force 1 | B18: 121 | D18: Bangalore | E18: 216 | G18: Premier III | H18: 4 | I18: 6 | J18: 2 | K18: 2 | L18: 4 | M18: 4 | N18: 3 | O18: 23 | P18: 25 | Q18: 23 | R18: 25 | S18: 121
A19: Air Jordan | B19: 133 | D19: Bengaluru | E19: 220 | G19: React Infinity | H19: 3 | I19: 3 | J19: 2 | K19: 4 | L19: 3 | M19: 3 | N19: 3 | O19: 32 | P19: 27 | Q19: 26 | R19: 28 | S19: 134
A20: Air Zoom | B20: 107 | D20: Delhi | E20: 438 | G20: SuperRep Go | H20: 9 | I20: 9 | J20: 3 | K20: 2 | L20: 9 | M20: 4 | N20: 2 | O20: 25 | P20: 28 | Q20: 42 | R20: 15 | S20: 148
A21: Blazer Mid | B21: 127 | D21: Hyderabad | E21: 403 | G21: Tiempo Legend | H21: 6 | I21: 2 | J21: 5 | K21: 1 | L21: 4 | M21: 3 | N21: 4 | O21: 21 | P21: 28 | Q21: 17 | R21: 21 | S21: 112
A22: Dunk Low | B22: 116 | D22: Kolkata | E22: 417 | G22: Waffle One | H22: 4 | I22: 3 | J22: 1 | K22: 6 | L22: 4 | M22: 1 | N22: 2 | O22: 36 | P22: 25 | Q22: 26 | R22: 29 | S22: 137 | U22: Row Labels | V22: Count of Order_ID | W22: Sum of Revenue | X22: Average of Revenue2
A23: Flex Trainer | B23: 141 | D23: Mumbai | E23: 418 | G23: Zoom Freak | H23: 3 | I23: 4 | J23: 3 | K23: 1 | L23: 1 | M23: 3 | N23: 4 | O23: 21 | P23: 23 | Q23: 28 | R23: 23 | S23: 114 | U23: Alphabet | V23: 1503 | W23: 406379.45 | X23: 270.37888
A24: Free RN | B24: 124 | D24: Pune | E24: 388 | G24: ZoomX Invincible | H24: 2 | I24: 5 | J24: 3 | K24: 3 | L24: 4 | M24: 2 | N24: 4 | O24: 27 | P24: 30 | Q24: 30 | R24: 30 | S24: 140 | U24: Missing | V24: 510 | W24: 157717.7 | X24: 309.25039
A25: Kyrie Flytrap | B25: 116 | D25: Grand Total | E25: 2500 | G25: Grand Total | H25: 76 | I25: 77 | J25: 61 | K25: 59 | L25: 86 | M25: 60 | N25: 68 | O25: 513 | P25: 478 | Q25: 510 | R25: 512 | S25: 2500 | U25: Number | V25: 487 | W25: 123087.14 | X25: 252.74567
A26: LeBron 20 | B26: 144 | U26: Grand Total | V26: 2500 | W26: 687184.29 | X26: 274.87372
A27: Mercurial Superfly | B27: 109 | D27: Row Labels | E27: Count of Units_Sold
A28: Metcon 7 | B28: 117 | D28: -1 | E28: 205
A29: Pegasus Turbo | B29: 109 | D29: 0 | E29: 224
A30: Phantom GT | B30: 130 | D30: 1 | E30: 203
A31: Premier III | B31: 121 | D31: 2 | E31: 234
A32: React Infinity | B32: 134 | D32: 3 | E32: 187
A33: SuperRep Go | B33: 148 | D33: 4 | E33: 212
A34: Tiempo Legend | B34: 112 | D34: (blank)
A35: Waffle One | B35: 137 | D35: Grand Total | E35: 1265
A36: Zoom Freak | B36: 114
A37: ZoomX Invincible | B37: 140
A38: Grand Total | B38: 2500

Sheet Nike_Sales_PreCleaned
A1: Order_ID | B1: Gender_Category | C1: Product_Line | D1: Product_Name | E1: Size | F1: Size_Type | G1: Size_Verification | H1: Valid_Size_Analysis | I1: Units_Sold | J1: Product_Status | K1: MRP | L1: Discount_Applied | M1: Discount_Verification | N1: Discount_Analysis | O1: Revenue | P1: Rev_Recalc | Q1: Rev_Verify | R1: Revenue_Analysis | S1: Order_Date | T1: OD_Status | U1: Valid_OD_Analysis | V1: Sales_Channel | W1: Region | X1: Region_Formatted | Y1: Profit | Z1: Profit_Status | AA1: Profit_Analysis | AC1: DATA QUALITY SUMMARY TABLE | AD1: Stats
A2: 2000 | B2: Kids | C2: Training | D2: SuperRep Go | E2: M | F2: =_xlfn.IFS(ISBLANK(Size),"Missing",ISNUMBER(Size),"Number",ISTEXT(Size),"Alphabet") -> Alphabet | G2: =IF(Size_Type ="Missing","Unknown",TRIM(Size)) -> M | H2: =IF(Size_Verification="Unknown","No","Yes") -> Yes | J2: =_xlfn.IFS(Units_Sold<0,"Check Return/Refund",Units_Sold=" ",Invalid,Units_Sold=0,"Available",Units_Sold>0,"Sold") -> Available | L2: 0.47 | M2: =IF(OR(Discount_Applied="",Discount_Applied>1,Discount_Applied<0),"Invalid","Valid") -> Valid | N2: =IF(PC_NikeSales[[#This Row],[Discount_Verification]]="Valid","Include","Exclude") -> Include | O2: 0 | P2: =IF(AND(Units_Sold<>"",MRP<>"",Discount_Applied<1),Units_Sold*MRP*(1-Discount_Applied),"Insufficient Data") -> Insufficient Data | Q2: =_xlfn.IFS(Rev_Recalc="Insufficient Data","Missing Information",Rev_Recalc<0,"Negative Revenue",Rev_Recalc=0,"No Recorded Revenue",Rev_Recalc>0,"Valid Revenue") -> Missing Information | R2: =IF(PC_NikeSales[[#This Row],[Rev_Verify]]="Valid Revenue","Include","Exclude") -> Exclude | S2: 45360 | T2: =IF(ISBLANK(Order_Date),"Missing Date",Order_Date) -> 45360 | U2: =IF(ISBLANK(Order_Date),"No","Yes") -> Yes | V2: Online | W2: bengaluru | X2: =PROPER(Region) -> Bengaluru | Y2: -770.45 | Z2: =IF(PC_NikeSales[[#This Row],[Profit]]<0,"Loss Making Sales",IF(PC_NikeSales[[#This Row],[Profit]]=0,"No Recorded Profit",IF(PC_NikeSales[[#This Row],[Profit]]>PC_NikeSales[Rev_Recalc],"Invalid Profit", "Valid Profit"))) -> Loss Making Sales | AA2: =IF(PC_NikeSales[[#This Row],[Profit_Status]]="Valid Profit","Include","Exclude") -> Exclude | AC2: % of Revenue Insufficent Data | AD2: =(COUNTIF(Rev_Recalc,"Insufficient Data")/2500)*100 -> 76.44
A3: 2001 | B3: Women | C3: Soccer | D3: Tiempo Legend | E3: M | F3: =_xlfn.IFS(ISBLANK(Size),"Missing",ISNUMBER(Size),"Number",ISTEXT(Size),"Alphabet") -> Alphabet | G3: =IF(Size_Type ="Missing","Unknown",TRIM(Size)) -> M | H3: =IF(Size_Verification="Unknown","No","Yes") -> Yes | I3: 3 | J3: =_xlfn.IFS(Units_Sold<0,"Check Return/Refund",Units_Sold=" ",Invalid,Units_Sold=0,"Available",Units_Sold>0,"Sold") -> Sold | K3: 4957.93 | M3: =IF(OR(Discount_Applied="",Discount_Applied>1,Discount_Applied<0),"Invalid","Valid") -> Invalid | N3: =IF(PC_NikeSales[[#This Row],[Discount_Verification]]="Valid","Include","Exclude") -> Exclude | O3: 0 | P3: =IF(AND(Units_Sold<>"",MRP<>"",Discount_Applied<1),Units_Sold*MRP*(1-Discount_Applied),"Insufficient Data") -> 14873.79 | Q3: =_xlfn.IFS(Rev_Recalc="Insufficient Data","Missing Information",Rev_Recalc<0,"Negative Revenue",Rev_Recalc=0,"No Recorded Revenue",Rev_Recalc>0,"Valid Revenue") -> Valid Revenue | R3: =IF(PC_NikeSales[[#This Row],[Rev_Verify]]="Valid Revenue","Include","Exclude") -> Include | S3: 45482 | T3: =IF(ISBLANK(Order_Date),"Missing Date",Order_Date) -> 45482 | U3: =IF(ISBLANK(Order_Date),"No","Yes") -> Yes | V3: Retail | W3: Hyderabad | X3: =PROPER(Region) -> Hyderabad | Y3: -112.53 | Z3: =IF(PC_NikeSales[[#This Row],[Profit]]<0,"Loss Making Sales",IF(PC_NikeSales[[#This Row],[Profit]]=0,"No Recorded Profit",IF(PC_NikeSales[[#This Row],[Profit]]>PC_NikeSales[Rev_Recalc],"Invalid Profit", "Valid Profit"))) -> Loss Making Sales | AA3: =IF(PC_NikeSales[[#This Row],[Profit_Status]]="Valid Profit","Include","Exclude") -> Exclude | AC3: % of Invalid Profit | AD3: =(COUNTIF(Z:Z, "Invalid Profit")/ROWS(Order_ID))*100 -> 12.2
A4: 2002 | B4: Women | C4: Soccer | D4: Premier III | E4: M | F4: =_xlfn.IFS(ISBLANK(Size),"Missing",ISNUMBER(Size),"Number",ISTEXT(Size),"Alphabet") -> Alphabet | G4: =IF(Size_Type ="Missing","Unknown",TRIM(Size)) -> M | H4: =IF(Size_Verification="Unknown","No","Yes") -> Yes | I4: 4 | J4: =_xlfn.IFS(Units_Sold<0,"Check Return/Refund",Units_Sold=" ",Invalid,Units_Sold=0,"Available",Units_Sold>0,"Sold") -> Sold | M4: =IF(OR(Discount_Applied="",Discount_Applied>1,Discount_Applied<0),"Invalid","Valid") -> Invalid | N4: =IF(PC_NikeSales[[#This Row],[Discount_Verification]]="Valid","Include","Exclude") -> Exclude | O4: 0 | P4: =IF(AND(Units_Sold<>"",MRP<>"",Discount_Applied<1),Units_Sold*MRP*(1-Discount_Applied),"Insufficient Data") -> Insufficient Data | Q4: =_xlfn.IFS(Rev_Recalc="Insufficient Data","Missing Information",Rev_Recalc<0,"Negative Revenue",Rev_Recalc=0,"No Recorded Revenue",Rev_Recalc>0,"Valid Revenue") -> Missing Information | R4: =IF(PC_NikeSales[[#This Row],[Rev_Verify]]="Valid Revenue","Include","Exclude") -> Exclude | T4: =IF(ISBLANK(Order_Date),"Missing Date",Order_Date) -> Missing Date | U4: =IF(ISBLANK(Order_Date),"No","Yes") -> No | V4: Retail | W4: Mumbai | X4: =PROPER(Region) -> Mumbai | Y4: 3337.34 | Z4: =IF(PC_NikeSales[[#This Row],[Profit]]<0,"Loss Making Sales",IF(PC_NikeSales[[#This Row],[Profit]]=0,"No Recorded Profit",IF($Y2>$P2,"Invalid Profit", "Valid Profit"))) -> Valid Profit | AA4: =IF(PC_NikeSales[[#This Row],[Profit_Status]]="Valid Profit","Include","Exclude") -> Include | AC4: % of Loss Making Sales | AD4: =(COUNTIF(Profit_Status,"Loss Making Sales")/2500)*100 -> 23.12
A5: 2003 | B5: Kids | C5: Lifestyle | D5: Blazer Mid | E5: L | F5: =_xlfn.IFS(ISBLANK(Size),"Missing",ISNUMBER(Size),"Number",ISTEXT(Size),"Alphabet") -> Alphabet | G5: =IF(Size_Type ="Missing","Unknown",TRIM(Size)) -> L | H5: =IF(Size_Verification="Unknown","No","Yes") -> Yes | J5: =_xlfn.IFS(Units_Sold<0,"Check Return/Refund",Units_Sold=" ",Invalid,Units_Sold=0,"Available",Units_Sold>0,"Sold") -> Available | K5: 9673.57 | M5: =IF(OR(Discount_Applied="",Discount_Applied>1,Discount_Applied<0),"Invalid","Valid") -> Invalid | N5: =IF(PC_NikeSales[[#This Row],[Discount_Verification]]="Valid","Include","Exclude") -> Exclude | O5: 0 | P5: =IF(AND(Units_Sold<>"",MRP<>"",Discount_Applied<1),Units_Sold*MRP*(1-Discount_Applied),"Insufficient Data") -> Insufficient Data | Q5: =_xlfn.IFS(Rev_Recalc="Insufficient Data","Missing Information",Rev_Recalc<0,"Negative Revenue",Rev_Recalc=0,"No Recorded Revenue",Rev_Recalc>0,"Valid Revenue") -> Missing Information | R5: =IF(PC_NikeSales[[#This Row],[Rev_Verify]]="Valid Revenue","Include","Exclude") -> Exclude | S5: 45569 | T5: =IF(ISBLANK(Order_Date),"Missing Date",Order_Date) -> 45569 | U5: =IF(ISBLANK(Order_Date),"No","Yes") -> Yes | V5: Online | W5: Pune | X5: =PROPER(Region) -> Pune | Y5: 3376.85 | Z5: =IF(PC_NikeSales[[#This Row],[Profit]]<0,"Loss Making Sales",IF(PC_NikeSales[[#This Row],[Profit]]=0,"No Recorded Profit",IF($Y3>$P3,"Invalid Profit", "Valid Profit"))) -> Valid Profit | AA5: =IF(PC_NikeSales[[#This Row],[Profit_Status]]="Valid Profit","Include","Exclude") -> Include | AC5: % of Missing Sizes | AD5: =(COUNTIF(Size_Type,"Missing")/2500)*100 -> 20.4
A6: 2004 | B6: Kids | C6: Running | D6: React Infinity | E6: XL | F6: =_xlfn.IFS(ISBLANK(Size),"Missing",ISNUMBER(Size),"Number",ISTEXT(Size),"Alphabet") -> Alphabet | G6: =IF(Size_Type ="Missing","Unknown",TRIM(Size)) -> XL | H6: =IF(Size_Verification="Unknown","No","Yes") -> Yes | J6: =_xlfn.IFS(Units_Sold<0,"Check Return/Refund",Units_Sold=" ",Invalid,Units_Sold=0,"Available",Units_Sold>0,"Sold") -> Available | M6: =IF(OR(Discount_Applied="",Discount_Applied>1,Discount_Applied<0),"Invalid","Valid") -> Invalid | N6: =IF(PC_NikeSales[[#This Row],[Discount_Verification]]="Valid","Include","Exclude") -> Exclude | O6: 0 | P6: =IF(AND(Units_Sold<>"",MRP<>"",Discount_Applied<1),Units_Sold*MRP*(1-Discount_Applied),"Insufficient Data") -> Insufficient Data | Q6: =_xlfn.IFS(Rev_Recalc="Insufficient Data","Missing Information",Rev_Recalc<0,"Negative Revenue",Rev_Recalc=0,"No Recorded Revenue",Rev_Recalc>0,"Valid Revenue") -> Missing Information | R6: =IF(PC_NikeSales[[#This Row],[Rev_Verify]]="Valid Revenue","Include","Exclude") -> Exclude | S6: 45547 | T6: =IF(ISBLANK(Order_Date),"Missing Date",Order_Date) -> 45547 | U6: =IF(ISBLANK(Order_Date),"No","Yes") -> Yes | V6: Retail | W6: Delhi | X6: =PROPER(Region) -> Delhi | Y6: 187.89 | Z6: =IF(PC_NikeSales[[#This Row],[Profit]]<0,"Loss Making Sales",IF(PC_NikeSales[[#This Row],[Profit]]=0,"No Recorded Profit",IF($Y4>$P4,"Invalid Profit", "Valid Profit"))) -> Valid Profit | AA6: =IF(PC_NikeSales[[#This Row],[Profit_Status]]="Valid Profit","Include","Exclude") -> Include | AC6: % of Missing Dates | AD6: =(COUNTIF(OD_Status,"Missing Date")/2500)*100 -> 24.64
A7: 2005 | B7: Women | C7: Training | D7: Flex Trainer | E7: M | F7: =_xlfn.IFS(ISBLANK(Size),"Missing",ISNUMBER(Size),"Number",ISTEXT(Size),"Alphabet") -> Alphabet | G7: =IF(Size_Type ="Missing","Unknown",TRIM(Size)) -> M | H7: =IF(Size_Verification="Unknown","No","Yes") -> Yes | I7: 1 | J7: =_xlfn.IFS(Units_Sold<0,"Check Return/Refund",Units_Sold=" ",Invalid,Units_Sold=0,"Available",Units_Sold>0,"Sold") -> Sold | K7: 7363.96 | M7: =IF(OR(Discount_Applied="",Discount_Applied>1,Discount_Applied<0),"Invalid","Valid") -> Invalid | N7: =IF(PC_NikeSales[[#This Row],[Discount_Verification]]="Valid","Include","Exclude") -> Exclude | O7: 0 | P7: =IF(AND(Units_Sold<>"",MRP<>"",Discount_Applied<1),Units_Sold*MRP*(1-Discount_Applied),"Insufficient Data") -> 7363.96 | Q7: =_xlfn.IFS(Rev_Recalc="Insufficient Data","Missing Information",Rev_Recalc<0,"Negative Revenue",Rev_Recalc=0,"No Recorded Revenue",Rev_Recalc>0,"Valid Revenue") -> Valid Revenue | R7: =IF(PC_NikeSales[[#This Row],[Rev_Verify]]="Valid Revenue","Include","Exclude") -> Include | T7: =IF(ISBLANK(Order_Date),"Missing Date",Order_Date) -> Missing Date | U7: =IF(ISBLANK(Order_Date),"No","Yes") -> No | V7: Retail | W7: Delhi | X7: =PROPER(Region) -> Delhi | Y7: 1415.98 | Z7: =IF(PC_NikeSales[[#This Row],[Profit]]<0,"Loss Making Sales",IF(PC_NikeSales[[#This Row],[Profit]]=0,"No Recorded Profit",IF($Y5>$P5,"Invalid Profit", "Valid Profit"))) -> Valid Profit | AA7: =IF(PC_NikeSales[[#This Row],[Profit_Status]]="Valid Profit","Include","Exclude") -> Include | AC7: % of Invalid Discounts | AD7: =(COUNTIF(M:M,"Invalid")/ROWS(Order_ID))*100 -> 73.92
A8: 2006 | B8: Men | C8: Training | D8: SuperRep Go | E8: M | F8: =_xlfn.IFS(ISBLANK(Size),"Missing",ISNUMBER(Size),"Number",ISTEXT(Size),"Alphabet") -> Alphabet | G8: =IF(Size_Type ="Missing","Unknown",TRIM(Size)) -> M | H8: =IF(Size_Verification="Unknown","No","Yes") -> Yes | J8: =_xlfn.IFS(Units_Sold<0,"Check Return/Refund",Units_Sold=" ",Invalid,Units_Sold=0,"Available",Units_Sold>0,"Sold") -> Available | K8: 6819.78 | M8: =IF(OR(Discount_Applied="",Discount_Applied>1,Discount_Applied<0),"Invalid","Valid") -> Invalid | N8: =IF(PC_NikeSales[[#This Row],[Discount_Verification]]="Valid","Include","Exclude") -> Exclude | O8: 0 | P8: =IF(AND(Units_Sold<>"",MRP<>"",Discount_Applied<1),Units_Sold*MRP*(1-Discount_Applied),"Insufficient Data") -> Insufficient Data | Q8: =_xlfn.IFS(Rev_Recalc="Insufficient Data","Missing Information",Rev_Recalc<0,"Negative Revenue",Rev_Recalc=0,"No Recorded Revenue",Rev_Recalc>0,"Valid Revenue") -> Missing Information | R8: =IF(PC_NikeSales[[#This Row],[Rev_Verify]]="Valid Revenue","Include","Exclude") -> Exclude | S8: 45812 | T8: =IF(ISBLANK(Order_Date),"Missing Date",Order_Date) -> 45812 | U8: =IF(ISBLANK(Order_Date),"No","Yes") -> Yes | V8: Online | W8: Bangalore | X8: =PROPER(Region) -> Bangalore | Y8: 1802.09 | Z8: =IF(PC_NikeSales[[#This Row],[Profit]]<0,"Loss Making Sales",IF(PC_NikeSales[[#This Row],[Profit]]=0,"No Recorded Profit",IF($Y6>$P6,"Invalid Profit", "Valid Profit"))) -> Valid Profit | AA8: =IF(PC_NikeSales[[#This Row],[Profit_Status]]="Valid Profit","Include","Exclude") -> Include | AC8: % of Included Rows | AD8: =(ROWS(CleanedSales)/2500)*100 -> 1.68
A9: 2007 | B9: Kids | C9: Training | D9: SuperRep Go | E9: M | F9: =_xlfn.IFS(ISBLANK(Size),"Missing",ISNUMBER(Size),"Number",ISTEXT(Size),"Alphabet") -> Alphabet | G9: =IF(Size_Type ="Missing","Unknown",TRIM(Size)) -> M | H9: =IF(Size_Verification="Unknown","No","Yes") -> Yes | I9: 1 | J9: =_xlfn.IFS(Units_Sold<0,"Check Return/Refund",Units_Sold=" ",Invalid,Units_Sold=0,"Available",Units_Sold>0,"Sold") -> Sold | L9: 0.32 | M9: =IF(OR(Discount_Applied="",Discount_Applied>1,Discount_Applied<0),"Invalid","Valid") -> Valid | N9: =IF(PC_NikeSales[[#This Row],[Discount_Verification]]="Valid","Include","Exclude") -> Include | O9: 0 | P9: =IF(AND(Units_Sold<>"",MRP<>"",Discount_Applied<1),Units_Sold*MRP*(1-Discount_Applied),"Insufficient Data") -> Insufficient Data | Q9: =_xlfn.IFS(Rev_Recalc="Insufficient Data","Missing Information",Rev_Recalc<0,"Negative Revenue",Rev_Recalc=0,"No Recorded Revenue",Rev_Recalc>0,"Valid Revenue") -> Missing Information | R9: =IF(PC_NikeSales[[#This Row],[Rev_Verify]]="Valid Revenue","Include","Exclude") -> Exclude | T9: =IF(ISBLANK(Order_Date),"Missing Date",Order_Date) -> Missing Date | U9: =IF(ISBLANK(Order_Date),"No","Yes") -> No | V9: Retail | W9: Bangalore | X9: =PROPER(Region) -> Bangalore | Y9: 2928.36 | Z9: =IF(PC_NikeSales[[#This Row],[Profit]]<0,"Loss Making Sales",IF(PC_NikeSales[[#This Row],[Profit]]=0,"No Recorded Profit",IF($Y7>$P7,"Invalid Profit", "Valid Profit"))) -> Valid Profit | AA9: =IF(PC_NikeSales[[#This Row],[Profit_Status]]="Valid Profit","Include","Exclude") -> Include | AC9: Total Original Rows | AD9: =ROWS(Order_ID) -> 2500
A10: 2008 | B10: Women | C10: Soccer | D10: Premier III | E10: 11 | F10: =_xlfn.IFS(ISBLANK(Size),"Missing",ISNUMBER(Size),"Number",ISTEXT(Size),"Alphabet") -> Number | G10: =IF(Size_Type ="Missing","Unknown",TRIM(Size)) -> 11 | H10: =IF(Size_Verification="Unknown","No","Yes") -> Yes | I10: -1 | J10: =_xlfn.IFS(Units_Sold<0,"Check Return/Refund",Units_Sold=" ",Invalid,Units_Sold=0,"Available",Units_Sold>0,"Sold") -> Check Return/Refund | M10: =IF(OR(Discount_Applied="",Discount_Applied>1,Discount_Applied<0),"Invalid","Valid") -> Invalid | N10: =IF(PC_NikeSales[[#This Row],[Discount_Verification]]="Valid","Include","Exclude") -> Exclude | O10: 0 | P10: =IF(AND(Units_Sold<>"",MRP<>"",Discount_Applied<1),Units_Sold*MRP*(1-Discount_Applied),"Insufficient Data") -> Insufficient Data | Q10: =_xlfn.IFS(Rev_Recalc="Insufficient Data","Missing Information",Rev_Recalc<0,"Negative Revenue",Rev_Recalc=0,"No Recorded Revenue",Rev_Recalc>0,"Valid Revenue") -> Missing Information | R10: =IF(PC_NikeSales[[#This Row],[Rev_Verify]]="Valid Revenue","Include","Exclude") -> Exclude | S10: 45576 | T10: =IF(ISBLANK(Order_Date),"Missing Date",Order_Date) -> 45576 | U10: =IF(ISBLANK(Order_Date),"No","Yes") -> Yes | V10: Online | W10: Hyderabad | X10: =PROPER(Region) -> Hyderabad | Y10: -731.18 | Z10: =IF(PC_NikeSales[[#This Row],[Profit]]<0,"Loss Making Sales",IF(PC_NikeSales[[#This Row],[Profit]]=0,"No Recorded Profit",IF(PC_NikeSales[[#This Row],[Profit]]>PC_NikeSales[Rev_Recalc],"Invalid Profit", "Valid Profit"))) -> Loss Making Sales | AA10: =IF(PC_NikeSales[[#This Row],[Profit_Status]]="Valid Profit","Include","Exclude") -> Exclude
A11: 2009 | B11: Men | C11: Soccer | D11: Mercurial Superfly | E11: M | F11: =_xlfn.IFS(ISBLANK(Size),"Missing",ISNUMBER(Size),"Number",ISTEXT(Size),"Alphabet") -> Alphabet | G11: =IF(Size_Type ="Missing","Unknown",TRIM(Size)) -> M | H11: =IF(Size_Verification="Unknown","No","Yes") -> Yes | I11: 4 | J11: =_xlfn.IFS(Units_Sold<0,"Check Return/Refund",Units_Sold=" ",Invalid,Units_Sold=0,"Available",Units_Sold>0,"Sold") -> Sold | M11: =IF(OR(Discount_Applied="",Discount_Applied>1,Discount_Applied<0),"Invalid","Valid") -> Invalid | N11: =IF(PC_NikeSales[[#This Row],[Discount_Verification]]="Valid","Include","Exclude") -> Exclude | O11: 0 | P11: =IF(AND(Units_Sold<>"",MRP<>"",Discount_Applied<1),Units_Sold*MRP*(1-Discount_Applied),"Insufficient Data") -> Insufficient Data | Q11: =_xlfn.IFS(Rev_Recalc="Insufficient Data","Missing Information",Rev_Recalc<0,"Negative Revenue",Rev_Recalc=0,"No Recorded Revenue",Rev_Recalc>0,"Valid Revenue") -> Missing Information | R11: =IF(PC_NikeSales[[#This Row],[Rev_Verify]]="Valid Revenue","Include","Exclude") -> Exclude | T11: =IF(ISBLANK(Order_Date),"Missing Date",Order_Date) -> Missing Date | U11: =IF(ISBLANK(Order_Date),"No","Yes") -> No | V11: Online | W11: Pune | X11: =PROPER(Region) -> Pune | Y11: 3929.61 | Z11: =IF(PC_NikeSales[[#This Row],[Profit]]<0,"Loss Making Sales",IF(PC_NikeSales[[#This Row],[Profit]]=0,"No Recorded Profit",IF($Y9>$P9,"Invalid Profit", "Valid Profit"))) -> Valid Profit | AA11: =IF(PC_NikeSales[[#This Row],[Profit_Status]]="Valid Profit","Include","Exclude") -> Include
A12: 2010 | B12: Kids | C12: Lifestyle | D12: Waffle One | E12: L | F12: =_xlfn.IFS(ISBLANK(Size),"Missing",ISNUMBER(Size),"Number",ISTEXT(Size),"Alphabet") -> Alphabet | G12: =IF(Size_Type ="Missing","Unknown",TRIM(Size)) -> L | H12: =IF(Size_Verification="Unknown","No","Yes") -> Yes | I12: 1 | J12: =_xlfn.IFS(Units_Sold<0,"Check Return/Refund",Units_Sold=" ",Invalid,Units_Sold=0,"Available",Units_Sold>0,"Sold") -> Sold | K12: 7949.83 | M12: =IF(OR(Discount_Applied="",Discount_Applied>1,Discount_Applied<0),"Invalid","Valid") -> Invalid | N12: =IF(PC_NikeSales[[#This Row],[Discount_Verification]]="Valid","Include","Exclude") -> Exclude | O12: 0 | P12: =IF(AND(Units_Sold<>"",MRP<>"",Discount_Applied<1),Units_Sold*MRP*(1-Discount_Applied),"Insufficient Data") -> 7949.83 | Q12: =_xlfn.IFS(Rev_Recalc="Insufficient Data","Missing Information",Rev_Recalc<0,"Negative Revenue",Rev_Recalc=0,"No Recorded Revenue",Rev_Recalc>0,"Valid Revenue") -> Valid Revenue | R12: =IF(PC_NikeSales[[#This Row],[Rev_Verify]]="Valid Revenue","Include","Exclude") -> Include | S12: 45673 | T12: =IF(ISBLANK(Order_Date),"Missing Date",Order_Date) -> 45673 | U12: =IF(ISBLANK(Order_Date),"No","Yes") -> Yes | V12: Online | W12: Pune | X12: =PROPER(Region) -> Pune | Y12: 1965.56 | Z12: =IF(PC_NikeSales[[#This Row],[Profit]]<0,"Loss Making Sales",IF(PC_NikeSales[[#This Row],[Profit]]=0,"No Recorded Profit",IF($Y10>$P10,"Invalid Profit", "Valid Profit"))) -> Valid Profit | AA12: =IF(PC_NikeSales[[#This Row],[Profit_Status]]="Valid Profit","Include","Exclude") -> Include
A13: 2011 | B13: Women | C13: Training | D13: Flex Trainer | E13: L | F13: =_xlfn.IFS(ISBLANK(Size),"Missing",ISNUMBER(Size),"Number",ISTEXT(Size),"Alphabet") -> Alphabet | G13: =IF(Size_Type ="Missing","Unknown",TRIM(Size)) -> L | H13: =IF(Size_Verification="Unknown","No","Yes") -> Yes | I13: -1 | J13: =_xlfn.IFS(Units_Sold<0,"Check Return/Refund",Units_Sold=" ",Invalid,Units_Sold=0,"Available",Units_Sold>0,"Sold") -> Check Return/Refund | K13: 9586.08 | M13: =IF(OR(Discount_Applied="",Discount_Applied>1,Discount_Applied<0),"Invalid","Valid") -> Invalid | N13: =IF(PC_NikeSales[[#This Row],[Discount_Verification]]="Valid","Include","Exclude") -> Exclude | O13: 0 | P13: =IF(AND(Units_Sold<>"",MRP<>"",Discount_Applied<1),Units_Sold*MRP*(1-Discount_Applied),"Insufficient Data") -> -9586.08 | Q13: =_xlfn.IFS(Rev_Recalc="Insufficient Data","Missing Information",Rev_Recalc<0,"Negative Revenue",Rev_Recalc=0,"No Recorded Revenue",Rev_Recalc>0,"Valid Revenue") -> Negative Revenue | R13: =IF(PC_NikeSales[[#This Row],[Rev_Verify]]="Valid Revenue","Include","Exclude") -> Exclude | T13: =IF(ISBLANK(Order_Date),"Missing Date",Order_Date) -> Missing Date | U13: =IF(ISBLANK(Order_Date),"No","Yes") -> No | V13: Retail | W13: Hyderabad | X13: =PROPER(Region) -> Hyderabad | Y13: 1667.08 | Z13: =IF(PC_NikeSales[[#This Row],[Profit]]<0,"Loss Making Sales",IF(PC_NikeSales[[#This Row],[Profit]]=0,"No Recorded Profit",IF(PC_NikeSales[[#This Row],[Profit]]>PC_NikeSales[Rev_Recalc],"Invalid Profit", "Valid Profit"))) -> Invalid Profit | AA13: =IF(PC_NikeSales[[#This Row],[Profit_Status]]="Valid Profit","Include","Exclude") -> Exclude
A14: 2018 | B14: Kids | C14: Lifestyle | D14: Blazer Mid | F14: =_xlfn.IFS(ISBLANK(Size),"Missing",ISNUMBER(Size),"Number",ISTEXT(Size),"Alphabet") -> Missing | G14: =IF(Size_Type ="Missing","Unknown",TRIM(Size)) -> Unknown | H14: =IF(Size_Verification="Unknown","No","Yes") -> No | I14: -1 | J14: =_xlfn.IFS(Units_Sold<0,"Check Return/Refund",Units_Sold=" ",Invalid,Units_Sold=0,"Available",Units_Sold>0,"Sold") -> Check Return/Refund | L14: 0.86 | M14: =IF(OR(Discount_Applied="",Discount_Applied>1,Discount_Applied<0),"Invalid","Valid") -> Valid | N14: =IF(PC_NikeSales[[#This Row],[Discount_Verification]]="Valid","Include","Exclude") -> Include | O14: 0 | P14: =IF(AND(Units_Sold<>"",MRP<>"",Discount_Applied<1),Units_Sold*MRP*(1-Discount_Applied),"Insufficient Data") -> Insufficient Data | Q14: =_xlfn.IFS(Rev_Recalc="Insufficient Data","Missing Information",Rev_Recalc<0,"Negative Revenue",Rev_Recalc=0,"No Recorded Revenue",Rev_Recalc>0,"Valid Revenue") -> Missing Information | R14: =IF(PC_NikeSales[[#This Row],[Rev_Verify]]="Valid Revenue","Include","Exclude") -> Exclude | S14: 45609 | T14: =IF(ISBLANK(Order_Date),"Missing Date",Order_Date) -> 45609 | U14: =IF(ISBLANK(Order_Date),"No","Yes") -> Yes | V14: Online | W14: Delhi | X14: =PROPER(Region) -> Delhi | Y14: 2109.48 | Z14: =IF(PC_NikeSales[[#This Row],[Profit]]<0,"Loss Making Sales",IF(PC_NikeSales[[#This Row],[Profit]]=0,"No Recorded Profit",IF($Y12>$P12,"Invalid Profit", "Valid Profit"))) -> Valid Profit | AA14: =IF(PC_NikeSales[[#This Row],[Profit_Status]]="Valid Profit","Include","Exclude") -> Include
A15: 2013 | B15: Kids | C15: Training | D15: SuperRep Go | F15: =_xlfn.IFS(ISBLANK(Size),"Missing",ISNUMBER(Size),"Number",ISTEXT(Size),"Alphabet") -> Missing | G15: =IF(Size_Type ="Missing","Unknown",TRIM(Size)) -> Unknown | H15: =IF(Size_Verification="Unknown","No","Yes") -> No | J15: =_xlfn.IFS(Units_Sold<0,"Check Return/Refund",Units_Sold=" ",Invalid,Units_Sold=0,"Available",Units_Sold>0,"Sold") -> Available | K15: 9671.05 | M15: =IF(OR(Discount_Applied="",Discount_Applied>1,Discount_Applied<0),"Invalid","Valid") -> Invalid | N15: =IF(PC_NikeSales[[#This Row],[Discount_Verification]]="Valid","Include","Exclude") -> Exclude | O15: 0 | P15: =IF(AND(Units_Sold<>"",MRP<>"",Discount_Applied<1),Units_Sold*MRP*(1-Discount_Applied),"Insufficient Data") -> Insufficient Data | Q15: =_xlfn.IFS(Rev_Recalc="Insufficient Data","Missing Information",Rev_Recalc<0,"Negative Revenue",Rev_Recalc=0,"No Recorded Revenue",Rev_Recalc>0,"Valid Revenue") -> Missing Information | R15: =IF(PC_NikeSales[[#This Row],[Rev_Verify]]="Valid Revenue","Include","Exclude") -> Exclude | S15: 45554 | T15: =IF(ISBLANK(Order_Date),"Missing Date",Order_Date) -> 45554 | U15: =IF(ISBLANK(Order_Date),"No","Yes") -> Yes | V15: Online | W15: Hyderabad | X15: =PROPER(Region) -> Hyderabad | Y15: 299.34 | Z15: =IF(PC_NikeSales[[#This Row],[Profit]]<0,"Loss Making Sales",IF(PC_NikeSales[[#This Row],[Profit]]=0,"No Recorded Profit",IF($Y13>$P13,"Invalid Profit", "Valid Profit"))) -> Invalid Profit | AA15: =IF(PC_NikeSales[[#This Row],[Profit_Status]]="Valid Profit","Include","Exclude") -> Exclude
A16: 2014 | B16: Women | C16: Running | D16: React Infinity | E16: 11 | F16: =_xlfn.IFS(ISBLANK(Size),"Missing",ISNUMBER(Size),"Number",ISTEXT(Size),"Alphabet") -> Number | G16: =IF(Size_Type ="Missing","Unknown",TRIM(Size)) -> 11 | H16: =IF(Size_Verification="Unknown","No","Yes") -> Yes | J16: =_xlfn.IFS(Units_Sold<0,"Check Return/Refund",Units_Sold=" ",Invalid,Units_Sold=0,"Available",Units_Sold>0,"Sold") -> Available | M16: =IF(OR(Discount_Applied="",Discount_Applied>1,Discount_Applied<0),"Invalid","Valid") -> Invalid | N16: =IF(PC_NikeSales[[#This Row],[Discount_Verification]]="Valid","Include","Exclude") -> Exclude | O16: 0 | P16: =IF(AND(Units_Sold<>"",MRP<>"",Discount_Applied<1),Units_Sold*MRP*(1-Discount_Applied),"Insufficient Data") -> Insufficient Data | Q16: =_xlfn.IFS(Rev_Recalc="Insufficient Data","Missing Information",Rev_Recalc<0,"Negative Revenue",Rev_Recalc=0,"No Recorded Revenue",Rev_Recalc>0,"Valid Revenue") -> Missing Information | R16: =IF(PC_NikeSales[[#This Row],[Rev_Verify]]="Valid Revenue","Include","Exclude") -> Exclude | S16: 45759 | T16: =IF(ISBLANK(Order_Date),"Missing Date",Order_Date) -> 45759 | U16: =IF(ISBLANK(Order_Date),"No","Yes") -> Yes | V16: Online | W16: Bangalore | X16: =PROPER(Region) -> Bangalore | Y16: -1044.4 | Z16: =IF(PC_NikeSales[[#This Row],[Profit]]<0,"Loss Making Sales",IF(PC_NikeSales[[#This Row],[Profit]]=0,"No Recorded Profit",IF(PC_NikeSales[[#This Row],[Profit]]>PC_NikeSales[Rev_Recalc],"Invalid Profit", "Valid Profit"))) -> Loss Making Sales | AA16: =IF(PC_NikeSales[[#This Row],[Profit_Status]]="Valid Profit","Include","Exclude") -> Exclude
A17: 2015 | B17: Kids | C17: Basketball | D17: Air Jordan | F17: =_xlfn.IFS(ISBLANK(Size),"Missing",ISNUMBER(Size),"Number",ISTEXT(Size),"Alphabet") -> Missing | G17: =IF(Size_Type ="Missing","Unknown",TRIM(Size)) -> Unknown | H17: =IF(Size_Verification="Unknown","No","Yes") -> No | J17: =_xlfn.IFS(Units_Sold<0,"Check Return/Refund",Units_Sold=" ",Invalid,Units_Sold=0,"Available",Units_Sold>0,"Sold") -> Available | K17: 3285.52 | M17: =IF(OR(Discount_Applied="",Discount_Applied>1,Discount_Applied<0),"Invalid","Valid") -> Invalid | N17: =IF(PC_NikeSales[[#This Row],[Discount_Verification]]="Valid","Include","Exclude") -> Exclude | O17: 0 | P17: =IF(AND(Units_Sold<>"",MRP<>"",Discount_Applied<1),Units_Sold*MRP*(1-Discount_Applied),"Insufficient Data") -> Insufficient Data | Q17: =_xlfn.IFS(Rev_Recalc="Insufficient Data","Missing Information",Rev_Recalc<0,"Negative Revenue",Rev_Recalc=0,"No Recorded Revenue",Rev_Recalc>0,"Valid Revenue") -> Missing Information | R17: =IF(PC_NikeSales[[#This Row],[Rev_Verify]]="Valid Revenue","Include","Exclude") -> Exclude | S17: 45808 | T17: =IF(ISBLANK(Order_Date),"Missing Date",Order_Date) -> 45808 | U17: =IF(ISBLANK(Order_Date),"No","Yes") -> Yes | V17: Retail | W17: Kolkata | X17: =PROPER(Region) -> Kolkata | Y17: 1193.21 | Z17: =IF(PC_NikeSales[[#This Row],[Profit]]<0,"Loss Making Sales",IF(PC_NikeSales[[#This Row],[Profit]]=0,"No Recorded Profit",IF($Y15>$P15,"Invalid Profit", "Valid Profit"))) -> Valid Profit | AA17: =IF(PC_NikeSales[[#This Row],[Profit_Status]]="Valid Profit","Include","Exclude") -> Include
A18: 2016 | B18: Women | C18: Basketball | D18: Air Jordan | E18: M | F18: =_xlfn.IFS(ISBLANK(Size),"Missing",ISNUMBER(Size),"Number",ISTEXT(Size),"Alphabet") -> Alphabet | G18: =IF(Size_Type ="Missing","Unknown",TRIM(Size)) -> M | H18: =IF(Size_Verification="Unknown","No","Yes") -> Yes | I18: 1 | J18: =_xlfn.IFS(Units_Sold<0,"Check Return/Refund",Units_Sold=" ",Invalid,Units_Sold=0,"Available",Units_Sold>0,"Sold") -> Sold | K18: 9871.75 | L18: 0.3 | M18: =IF(OR(Discount_Applied="",Discount_Applied>1,Discount_Applied<0),"Invalid","Valid") -> Valid | N18: =IF(PC_NikeSales[[#This Row],[Discount_Verification]]="Valid","Include","Exclude") -> Include | O18: 6910.22 | P18: =IF(AND(Units_Sold<>"",MRP<>"",Discount_Applied<1),Units_Sold*MRP*(1-Discount_Applied),"Insufficient Data") -> 6910.225 | Q18: =_xlfn.IFS(Rev_Recalc="Insufficient Data","Missing Information",Rev_Recalc<0,"Negative Revenue",Rev_Recalc=0,"No Recorded Revenue",Rev_Recalc>0,"Valid Revenue") -> Valid Revenue | R18: =IF(PC_NikeSales[[#This Row],[Rev_Verify]]="Valid Revenue","Include","Exclude") -> Include | T18: =IF(ISBLANK(Order_Date),"Missing Date",Order_Date) -> Missing Date | U18: =IF(ISBLANK(Order_Date),"No","Yes") -> No | V18: Retail | W18: Hyderabad | X18: =PROPER(Region) -> Hyderabad | Y18: 2452.69 | Z18: =IF(PC_NikeSales[[#This Row],[Profit]]<0,"Loss Making Sales",IF(PC_NikeSales[[#This Row],[Profit]]=0,"No Recorded Profit",IF($Y16>$P16,"Invalid Profit", "Valid Profit"))) -> Valid Profit | AA18: =IF(PC_NikeSales[[#This Row],[Profit_Status]]="Valid Profit","Include","Exclude") -> Include
A19: 2017 | B19: Women | C19: Basketball | D19: Air Jordan | E19: 9 | F19: =_xlfn.IFS(ISBLANK(Size),"Missing",ISNUMBER(Size),"Number",ISTEXT(Size),"Alphabet") -> Number | G19: =IF(Size_Type ="Missing","Unknown",TRIM(Size)) -> 9 | H19: =IF(Size_Verification="Unknown","No","Yes") -> Yes | I19: 4 | J19: =_xlfn.IFS(Units_Sold<0,"Check Return/Refund",Units_Sold=" ",Invalid,Units_Sold=0,"Available",Units_Sold>0,"Sold") -> Sold | M19: =IF(OR(Discount_Applied="",Discount_Applied>1,Discount_Applied<0),"Invalid","Valid") -> Invalid | N19: =IF(PC_NikeSales[[#This Row],[Discount_Verification]]="Valid","Include","Exclude") -> Exclude | O19: 0 | P19: =IF(AND(Units_Sold<>"",MRP<>"",Discount_Applied<1),Units_Sold*MRP*(1-Discount_Applied),"Insufficient Data") -> Insufficient Data | Q19: =_xlfn.IFS(Rev_Recalc="Insufficient Data","Missing Information",Rev_Recalc<0,"Negative Revenue",Rev_Recalc=0,"No Recorded Revenue",Rev_Recalc>0,"Valid Revenue") -> Missing Information | R19: =IF(PC_NikeSales[[#This Row],[Rev_Verify]]="Valid Revenue","Include","Exclude") -> Exclude | S19: 45733 | T19: =IF(ISBLANK(Order_Date),"Missing Date",Order_Date) -> 45733 | U19: =IF(ISBLANK(Order_Date),"No","Yes") -> Yes | V19: Retail | W19: Delhi | X19: =PROPER(Region) -> Delhi | Y19: 1946.24 | Z19: =IF(PC_NikeSales[[#This Row],[Profit]]<0,"Loss Making Sales",IF(PC_NikeSales[[#This Row],[Profit]]=0,"No Recorded Profit",IF($Y17>$P17,"Invalid Profit", "Valid Profit"))) -> Valid Profit | AA19: =IF(PC_NikeSales[[#This Row],[Profit_Status]]="Valid Profit","Include","Exclude") -> Include
A20: 2018 | B20: Men | C20: Training | D20: Metcon 7 | E20: XL | F20: =_xlfn.IFS(ISBLANK(Size),"Missing",ISNUMBER(Size),"Number",ISTEXT(Size),"Alphabet") -> Alphabet | G20: =IF(Size_Type ="Missing","Unknown",TRIM(Size)) -> XL | H20: =IF(Size_Verification="Unknown","No","Yes") -> Yes | I20: 0 | J20: =_xlfn.IFS(Units_Sold<0,"Check Return/Refund",Units_Sold=" ",Invalid,Units_Sold=0,"Available",Units_Sold>0,"Sold") -> Available | L20: 1.17 | M20: =IF(OR(Discount_Applied="",Discount_Applied>1,Discount_Applied<0),"Invalid","Valid") -> Invalid | N20: =IF(PC_NikeSales[[#This Row],[Discount_Verification]]="Valid","Include","Exclude") -> Exclude | O20: 0 | P20: =IF(AND(Units_Sold<>"",MRP<>"",Discount_Applied<1),Units_Sold*MRP*(1-Discount_Applied),"Insufficient Data") -> Insufficient Data | Q20: =_xlfn.IFS(Rev_Recalc="Insufficient Data","Missing Information",Rev_Recalc<0,"Negative Revenue",Rev_Recalc=0,"No Recorded Revenue",Rev_Recalc>0,"Valid Revenue") -> Missing Information | R20: =IF(PC_NikeSales[[#This Row],[Rev_Verify]]="Valid Revenue","Include","Exclude") -> Exclude | T20: =IF(ISBLANK(Order_Date),"Missing Date",Order_Date) -> Missing Date | U20: =IF(ISBLANK(Order_Date),"No","Yes") -> No | V20: Online | W20: bengaluru | X20: =PROPER(Region) -> Bengaluru | Y20: -966.89 | Z20: =IF(PC_NikeSales[[#This Row],[Profit]]<0,"Loss Making Sales",IF(PC_NikeSales[[#This Row],[Profit]]=0,"No Recorded Profit",IF(PC_NikeSales[[#This Row],[Profit]]>PC_NikeSales[Rev_Recalc],"Invalid Profit", "Valid Profit"))) -> Loss Making Sales | AA20: =IF(PC_NikeSales[[#This Row],[Profit_Status]]="Valid Profit","Include","Exclude") -> Exclude
A21: 2019 | B21: Kids | C21: Running | D21: Air Zoom | E21: 6 | F21: =_xlfn.IFS(ISBLANK(Size),"Missing",ISNUMBER(Size),"Number",ISTEXT(Size),"Alphabet") -> Number | G21: =IF(Size_Type ="Missing","Unknown",TRIM(Size)) -> 6 | H21: =IF(Size_Verification="Unknown","No","Yes") -> Yes | I21: 0 | J21: =_xlfn.IFS(Units_Sold<0,"Check Return/Refund",Units_Sold=" ",Invalid,Units_Sold=0,"Available",Units_Sold>0,"Sold") -> Available | K21: 3424.06 | L21: 0.32 | M21: =IF(OR(Discount_Applied="",Discount_Applied>1,Discount_Applied<0),"Invalid","Valid") -> Valid | N21: =IF(PC_NikeSales[[#This Row],[Discount_Verification]]="Valid","Include","Exclude") -> Include | O21: 0 | P21: =IF(AND(Units_Sold<>"",MRP<>"",Discount_Applied<1),Units_Sold*MRP*(1-Discount_Applied),"Insufficient Data") -> 0 | Q21: =_xlfn.IFS(Rev_Recalc="Insufficient Data","Missing Information",Rev_Recalc<0,"Negative Revenue",Rev_Recalc=0,"No Recorded Revenue",Rev_Recalc>0,"Valid Revenue") -> No Recorded Revenue | R21: =IF(PC_NikeSales[[#This Row],[Rev_Verify]]="Valid Revenue","Include","Exclude") -> Exclude | S21: 45674 | T21: =IF(ISBLANK(Order_Date),"Missing Date",Order_Date) -> 45674 | U21: =IF(ISBLANK(Order_Date),"No","Yes") -> Yes | V21: Online | W21: Hyderabad | X21: =PROPER(Region) -> Hyderabad | Y21: 1915.24 | Z21: =IF(PC_NikeSales[[#This Row],[Profit]]<0,"Loss Making Sales",IF(PC_NikeSales[[#This Row],[Profit]]=0,"No Recorded Profit",IF(PC_NikeSales[[#This Row],[Profit]]>PC_NikeSales[Rev_Recalc],"Invalid Profit", "Valid Profit"))) -> Invalid Profit | AA21: =IF(PC_NikeSales[[#This Row],[Profit_Status]]="Valid Profit","Include","Exclude") -> Exclude
A22: 2020 | B22: Kids | C22: Soccer | D22: Tiempo Legend | E22: L | F22: =_xlfn.IFS(ISBLANK(Size),"Missing",ISNUMBER(Size),"Number",ISTEXT(Size),"Alphabet") -> Alphabet | G22: =IF(Size_Type ="Missing","Unknown",TRIM(Size)) -> L | H22: =IF(Size_Verification="Unknown","No","Yes") -> Yes | I22: -1 | J22: =_xlfn.IFS(Units_Sold<0,"Check Return/Refund",Units_Sold=" ",Invalid,Units_Sold=0,"Available",Units_Sold>0,"Sold") -> Check Return/Refund | L22: 0.67 | M22: =IF(OR(Discount_Applied="",Discount_Applied>1,Discount_Applied<0),"Invalid","Valid") -> Valid | N22: =IF(PC_NikeSales[[#This Row],[Discount_Verification]]="Valid","Include","Exclude") -> Include | O22: 0 | P22: =IF(AND(Units_Sold<>"",MRP<>"",Discount_Applied<1),Units_Sold*MRP*(1-Discount_Applied),"Insufficient Data") -> Insufficient Data | Q22: =_xlfn.IFS(Rev_Recalc="Insufficient Data","Missing Information",Rev_Recalc<0,"Negative Revenue",Rev_Recalc=0,"No Recorded Revenue",Rev_Recalc>0,"Valid Revenue") -> Missing Information | R22: =IF(PC_NikeSales[[#This Row],[Rev_Verify]]="Valid Revenue","Include","Exclude") -> Exclude | S22: 45744 | T22: =IF(ISBLANK(Order_Date),"Missing Date",Order_Date) -> 45744 | U22: =IF(ISBLANK(Order_Date),"No","Yes") -> Yes | V22: Retail | W22: Mumbai | X22: =PROPER(Region) -> Mumbai | Y22: 439.96 | Z22: =IF(PC_NikeSales[[#This Row],[Profit]]<0,"Loss Making Sales",IF(PC_NikeSales[[#This Row],[Profit]]=0,"No Recorded Profit",IF($Y20>$P20,"Invalid Profit", "Valid Profit"))) -> Valid Profit | AA22: =IF(PC_NikeSales[[#This Row],[Profit_Status]]="Valid Profit","Include","Exclude") -> Include
A23: 2021 | B23: Men | C23: Running | D23: Free RN | E23: L | F23: =_xlfn.IFS(ISBLANK(Size),"Missing",ISNUMBER(Size),"Number",ISTEXT(Size),"Alphabet") -> Alphabet | G23: =IF(Size_Type ="Missing","Unknown",TRIM(Size)) -> L | H23: =IF(Size_Verification="Unknown","No","Yes") -> Yes | I23: -1 | J23: =_xlfn.IFS(Units_Sold<0,"Check Return/Refund",Units_Sold=" ",Invalid,Units_Sold=0,"Available",Units_Sold>0,"Sold") -> Check Return/Refund | K23: 7086.7 | L23: 0.66 | M23: =IF(OR(Discount_Applied="",Discount_Applied>1,Discount_Applied<0),"Invalid","Valid") -> Valid | N23: =IF(PC_NikeSales[[#This Row],[Discount_Verification]]="Valid","Include","Exclude") -> Include | O23: -2409.48 | P23: =IF(AND(Units_Sold<>"",MRP<>"",Discount_Applied<1),Units_Sold*MRP*(1-Discount_Applied),"Insufficient Data") -> -2409.478 | Q23: =_xlfn.IFS(Rev_Recalc="Insufficient Data","Missing Information",Rev_Recalc<0,"Negative Revenue",Rev_Recalc=0,"No Recorded Revenue",Rev_Recalc>0,"Valid Revenue") -> Negative Revenue | R23: =IF(PC_NikeSales[[#This Row],[Rev_Verify]]="Valid Revenue","Include","Exclude") -> Exclude | S23: 45615 | T23: =IF(ISBLANK(Order_Date),"Missing Date",Order_Date) -> 45615 | U23: =IF(ISBLANK(Order_Date),"No","Yes") -> Yes | V23: Retail | W23: Hyderabad | X23: =PROPER(Region) -> Hyderabad | Y23: -1120.49 | Z23: =IF(PC_NikeSales[[#This Row],[Profit]]<0,"Loss Making Sales",IF(PC_NikeSales[[#This Row],[Profit]]=0,"No Recorded Profit",IF(PC_NikeSales[[#This Row],[Profit]]>PC_NikeSales[Rev_Recalc],"Invalid Profit", "Valid Profit"))) -> Loss Making Sales | AA23: =IF(PC_NikeSales[[#This Row],[Profit_Status]]="Valid Profit","Include","Exclude") -> Exclude
A24: 2022 | B24: Women | C24: Soccer | D24: Premier III | E24: M | F24: =_xlfn.IFS(ISBLANK(Size),"Missing",ISNUMBER(Size),"Number",ISTEXT(Size),"Alphabet") -> Alphabet | G24: =IF(Size_Type ="Missing","Unknown",TRIM(Size)) -> M | H24: =IF(Size_Verification="Unknown","No","Yes") -> Yes | J24: =_xlfn.IFS(Units_Sold<0,"Check Return/Refund",Units_Sold=" ",Invalid,Units_Sold=0,"Available",Units_Sold>0,"Sold") -> Available | M24: =IF(OR(Discount_Applied="",Discount_Applied>1,Discount_Applied<0),"Invalid","Valid") -> Invalid | N24: =IF(PC_NikeSales[[#This Row],[Discount_Verification]]="Valid","Include","Exclude") -> Exclude | O24: 0 | P24: =IF(AND(Units_Sold<>"",MRP<>"",Discount_Applied<1),Units_Sold*MRP*(1-Discount_Applied),"Insufficient Data") -> Insufficient Data | Q24: =_xlfn.IFS(Rev_Recalc="Insufficient Data","Missing Information",Rev_Recalc<0,"Negative Revenue",Rev_Recalc=0,"No Recorded Revenue",Rev_Recalc>0,"Valid Revenue") -> Missing Information | R24: =IF(PC_NikeSales[[#This Row],[Rev_Verify]]="Valid Revenue","Include","Exclude") -> Exclude | S24: 45559 | T24: =IF(ISBLANK(Order_Date),"Missing Date",Order_Date) -> 45559 | U24: =IF(ISBLANK(Order_Date),"No","Yes") -> Yes | V24: Online | W24: Pune | X24: =PROPER(Region) -> Pune | Y24: 3427.16 | Z24: =IF(PC_NikeSales[[#This Row],[Profit]]<0,"Loss Making Sales",IF(PC_NikeSales[[#This Row],[Profit]]=0,"No Recorded Profit",IF($Y22>$P22,"Invalid Profit", "Valid Profit"))) -> Valid Profit | AA24: =IF(PC_NikeSales[[#This Row],[Profit_Status]]="Valid Profit","Include","Exclude") -> Include
A25: 2023 | B25: Men | C25: Lifestyle | D25: Waffle One | E25: M | F25: =_xlfn.IFS(ISBLANK(Size),"Missing",ISNUMBER(Size),"Number",ISTEXT(Size),"Alphabet") -> Alphabet | G25: =IF(Size_Type ="Missing","Unknown",TRIM(Size)) -> M | H25: =IF(Size_Verification="Unknown","No","Yes") -> Yes | J25: =_xlfn.IFS(Units_Sold<0,"Check Return/Refund",Units_Sold=" ",Invalid,Units_Sold=0,"Available",Units_Sold>0,"Sold") -> Available | K25: 5003.95 | M25: =IF(OR(Discount_Applied="",Discount_Applied>1,Discount_Applied<0),"Invalid","Valid") -> Invalid | N25: =IF(PC_NikeSales[[#This Row],[Discount_Verification]]="Valid","Include","Exclude") -> Exclude | O25: 0 | P25: =IF(AND(Units_Sold<>"",MRP<>"",Discount_Applied<1),Units_Sold*MRP*(1-Discount_Applied),"Insufficient Data") -> Insufficient Data | Q25: =_xlfn.IFS(Rev_Recalc="Insufficient Data","Missing Information",Rev_Recalc<0,"Negative Revenue",Rev_Recalc=0,"No Recorded Revenue",Rev_Recalc>0,"Valid Revenue") -> Missing Information | R25: =IF(PC_NikeSales[[#This Row],[Rev_Verify]]="Valid Revenue","Include","Exclude") -> Exclude | S25: 45667 | T25: =IF(ISBLANK(Order_Date),"Missing Date",Order_Date) -> 45667 | U25: =IF(ISBLANK(Order_Date),"No","Yes") -> Yes | V25: Online | W25: Mumbai | X25: =PROPER(Region) -> Mumbai | Y25: 1498.37 | Z25: =IF(PC_NikeSales[[#This Row],[Profit]]<0,"Loss Making Sales",IF(PC_NikeSales[[#This Row],[Profit]]=0,"No Recorded Profit",IF($Y23>$P23,"Invalid Profit", "Valid Profit"))) -> Invalid Profit | AA25: =IF(PC_NikeSales[[#This Row],[Profit_Status]]="Valid Profit","Include","Exclude") -> Exclude
A26: 2024 | B26: Kids | C26: Training | D26: SuperRep Go | E26: XL | F26: =_xlfn.IFS(ISBLANK(Size),"Missing",ISNUMBER(Size),"Number",ISTEXT(Size),"Alphabet") -> Alphabet | G26: =IF(Size_Type ="Missing","Unknown",TRIM(Size)) -> XL | H26: =IF(Size_Verification="Unknown","No","Yes") -> Yes | I26: 0 | J26: =_xlfn.IFS(Units_Sold<0,"Check Return/Refund",Units_Sold=" ",Invalid,Units_Sold=0,"Available",Units_Sold>0,"Sold") -> Available | L26: 0.5 | M26: =IF(OR(Discount_Applied="",Discount_Applied>1,Discount_Applied<0),"Invalid","Valid") -> Valid | N26: =IF(PC_NikeSales[[#This Row],[Discount_Verification]]="Valid","Include","Exclude") -> Include | O26: 0 | P26: =IF(AND(Units_Sold<>"",MRP<>"",Discount_Applied<1),Units_Sold*MRP*(1-Discount_Applied),"Insufficient Data") -> Insufficient Data | Q26: =_xlfn.IFS(Rev_Recalc="Insufficient Data","Missing Information",Rev_Recalc<0,"Negative Revenue",Rev_Recalc=0,"No Recorded Revenue",Rev_Recalc>0,"Valid Revenue") -> Missing Information | R26: =IF(PC_NikeSales[[#This Row],[Rev_Verify]]="Valid Revenue","Include","Exclude") -> Exclude | S26: 45654 | T26: =IF(ISBLANK(Order_Date),"Missing Date",Order_Date) -> 45654 | U26: =IF(ISBLANK(Order_Date),"No","Yes") -> Yes | V26: Retail | W26: Bangalore | X26: =PROPER(Region) -> Bangalore | Y26: 1842.35 | Z26: =IF(PC_NikeSales[[#This Row],[Profit]]<0,"Loss Making Sales",IF(PC_NikeSales[[#This Row],[Profit]]=0,"No Recorded Profit",IF($Y24>$P24,"Invalid Profit", "Valid Profit"))) -> Valid Profit | AA26: =IF(PC_NikeSales[[#This Row],[Profit_Status]]="Valid Profit","Include","Exclude") -> Include
A27: 2025 | B27: Women | C27: Basketball | D27: Kyrie Flytrap | E27: M | F27: =_xlfn.IFS(ISBLANK(Size),"Missing",ISNUMBER(Size),"Number",ISTEXT(Size),"Alphabet") -> Alphabet | G27: =IF(Size_Type ="Missing","Unknown",TRIM(Size)) -> M | H27: =IF(Size_Verification="Unknown","No","Yes") -> Yes | I27: 3 | J27: =_xlfn.IFS(Units_Sold<0,"Check Return/Refund",Units_Sold=" ",Invalid,Units_Sold=0,"Available",Units_Sold>0,"Sold") -> Sold | K27: 9820.5 | M27: =IF(OR(Discount_Applied="",Discount_Applied>1,Discount_Applied<0),"Invalid","Valid") -> Invalid | N27: =IF(PC_NikeSales[[#This Row],[Discount_Verification]]="Valid","Include","Exclude") -> Exclude | O27: 0 | P27: =IF(AND(Units_Sold<>"",MRP<>"",Discount_Applied<1),Units_Sold*MRP*(1-Discount_Applied),"Insufficient Data") -> 29461.5 | Q27: =_xlfn.IFS(Rev_Recalc="Insufficient Data","Missing Information",Rev_Recalc<0,"Negative Revenue",Rev_Recalc=0,"No Recorded Revenue",Rev_Recalc>0,"Valid Revenue") -> Valid Revenue | R27: =IF(PC_NikeSales[[#This Row],[Rev_Verify]]="Valid Revenue","Include","Exclude") -> Include | T27: =IF(ISBLANK(Order_Date),"Missing Date",Order_Date) -> Missing Date | U27: =IF(ISBLANK(Order_Date),"No","Yes") -> No | V27: Retail | W27: Mumbai | X27: =PROPER(Region) -> Mumbai | Y27: 1900.15 | Z27: =IF(PC_NikeSales[[#This Row],[Profit]]<0,"Loss Making Sales",IF(PC_NikeSales[[#This Row],[Profit]]=0,"No Recorded Profit",IF($Y25>$P25,"Invalid Profit", "Valid Profit"))) -> Valid Profit | AA27: =IF(PC_NikeSales[[#This Row],[Profit_Status]]="Valid Profit","Include","Exclude") -> Include
A28: 2026 | B28: Kids | C28: Lifestyle | D28: Blazer Mid | E28: XL | F28: =_xlfn.IFS(ISBLANK(Size),"Missing",ISNUMBER(Size),"Number",ISTEXT(Size),"Alphabet") -> Alphabet | G28: =IF(Size_Type ="Missing","Unknown",TRIM(Size)) -> XL | H28: =IF(Size_Verification="Unknown","No","Yes") -> Yes | I28: 1 | J28: =_xlfn.IFS(Units_Sold<0,"Check Return/Refund",Units_Sold=" ",Invalid,Units_Sold=0,"Available",Units_Sold>0,"Sold") -> Sold | L28: 0.16 | M28: =IF(OR(Discount_Applied="",Discount_Applied>1,Discount_Applied<0),"Invalid","Valid") -> Valid | N28: =IF(PC_NikeSales[[#This Row],[Discount_Verification]]="Valid","Include","Exclude") -> Include | O28: 0 | P28: =IF(AND(Units_Sold<>"",MRP<>"",Discount_Applied<1),Units_Sold*MRP*(1-Discount_Applied),"Insufficient Data") -> Insufficient Data | Q28: =_xlfn.IFS(Rev_Recalc="Insufficient Data","Missing Information",Rev_Recalc<0,"Negative Revenue",Rev_Recalc=0,"No Recorded Revenue",Rev_Recalc>0,"Valid Revenue") -> Missing Information | R28: =IF(PC_NikeSales[[#This Row],[Rev_Verify]]="Valid Revenue","Include","Exclude") -> Exclude | S28: 45514 | T28: =IF(ISBLANK(Order_Date),"Missing Date",Order_Date) -> 45514 | U28: =IF(ISBLANK(Order_Date),"No","Yes") -> Yes | V28: Retail | W28: Kolkata | X28: =PROPER(Region) -> Kolkata | Y28: 2301.64 | Z28: =IF(PC_NikeSales[[#This Row],[Profit]]<0,"Loss Making Sales",IF(PC_NikeSales[[#This Row],[Profit]]=0,"No Recorded Profit",IF($Y26>$P26,"Invalid Profit", "Valid Profit"))) -> Valid Profit | AA28: =IF(PC_NikeSales[[#This Row],[Profit_Status]]="Valid Profit","Include","Exclude") -> Include
A29: 2027 | B29: Men | C29: Basketball | D29: Zoom Freak | E29: XL | F29: =_xlfn.IFS(ISBLANK(Size),"Missing",ISNUMBER(Size),"Number",ISTEXT(Size),"Alphabet") -> Alphabet | G29: =IF(Size_Type ="Missing","Unknown",TRIM(Size)) -> XL | H29: =IF(Size_Verification="Unknown","No","Yes") -> Yes | J29: =_xlfn.IFS(Units_Sold<0,"Check Return/Refund",Units_Sold=" ",Invalid,Units_Sold=0,"Available",Units_Sold>0,"Sold") -> Available | L29: 0.22 | M29: =IF(OR(Discount_Applied="",Discount_Applied>1,Discount_Applied<0),"Invalid","Valid") -> Valid | N29: =IF(PC_NikeSales[[#This Row],[Discount_Verification]]="Valid","Include","Exclude") -> Include | O29: 0 | P29: =IF(AND(Units_Sold<>"",MRP<>"",Discount_Applied<1),Units_Sold*MRP*(1-Discount_Applied),"Insufficient Data") -> Insufficient Data | Q29: =_xlfn.IFS(Rev_Recalc="Insufficient Data","Missing Information",Rev_Recalc<0,"Negative Revenue",Rev_Recalc=0,"No Recorded Revenue",Rev_Recalc>0,"Valid Revenue") -> Missing Information | R29: =IF(PC_NikeSales[[#This Row],[Rev_Verify]]="Valid Revenue","Include","Exclude") -> Exclude | T29: =IF(ISBLANK(Order_Date),"Missing Date",Order_Date) -> Missing Date | U29: =IF(ISBLANK(Order_Date),"No","Yes") -> No | V29: Online | W29: Pune | X29: =PROPER(Region) -> Pune | Y29: -138.74 | Z29: =IF(PC_NikeSales[[#This Row],[Profit]]<0,"Loss Making Sales",IF(PC_NikeSales[[#This Row],[Profit]]=0,"No Recorded Profit",IF(PC_NikeSales[[#This Row],[Profit]]>PC_NikeSales[Rev_Recalc],"Invalid Profit", "Valid Profit"))) -> Loss Making Sales | AA29: =IF(PC_NikeSales[[#This Row],[Profit_Status]]="Valid Profit","Include","Exclude") -> Exclude
